Workbook

Sheet Match Schedule (raw)
A1: Match | B1: Date | C1: Group | D1: Team 1 | E1: Team 2 | F1: Stadium | G1: City
A2: 1 | B2: 46184 | C2: A | D2: Mexico | E2: South Africa | F2: Mexico City Stadium | G2: Mexico City
A3: 2 | B3: 46184 | C3: A | D3: Korea Republic | E3: Denmark | F3: Guadalajara Stadium | G3: Guadalajara
A4: 3 | B4: 46191 | C4: A | D4: Denmark | E4: South Africa | F4: Atlanta Stadium | G4: Atlanta
A5: 4 | B5: 46191 | C5: A | D5: Mexico | E5: Korea Republic | F5: Guadalajara Stadium | G5: Guadalajara
A6: 5 | B6: 46197 | C6: A | D6: Denmark | E6: Mexico | F6: Mexico City Stadium | G6: Mexico City
A7: 6 | B7: 46197 | C7: A | D7: South Africa | E7: Korea Republic | F7: Monterrey Stadium | G7: Monterrey
A8: 7 | B8: 46185 | C8: B | D8: Canada | E8: Italy | F8: Toronto Stadium | G8: Toronto
A9: 8 | B9: 46186 | C9: B | D9: Qatar | E9: Switzerland | F9: San Francisco Bay Area Stadium | G9: Santa Clara
A10: 9 | B10: 46191 | C10: B | D10: Switzerland | E10: Italy | F10: Los Angeles Stadium | G10: Inglewood
A11: 10 | B11: 46191 | C11: B | D11: Canada | E11: Qatar | F11: Vancouver Stadium | G11: Vancouver
A12: 11 | B12: 46197 | C12: B | D12: Switzerland | E12: Canada | F12: Vancouver Stadium | G12: Vancouver
A13: 12 | B13: 46197 | C13: B | D13: Italy | E13: Qatar | F13: Seattle Stadium | G13: Seattle
... A73: 72 | B73: 46200 | C73: L | D73: Croatia | E73: Ghana | F73: Philadelphia Stadium | G73: Philadelphia

Sheet Stadium
A1: Stadium Name | B1: FIFA Name | C1: Address | D1: City | E1: Country | F1: Capacity | G1: Seating capacity (fans from a nation) | H1: No. of group matchs | I1: Probability of each stadium being used
A2: MetLife Stadium | B2: New York New Jersey Stadium | C2: 1 MetLife Stadium Dr, East Rutherford, NJ 07073, USA | D2: East Rutherford | E2: USA | F2: 78576 | G2: =F2*(91/100)*(12/100) -> 8580.4992 | H2: 72 | I2: =4.5/$H$2 -> 0.0625
A3: Estadio Azteca | B3: Mexico City Stadium | C3: Calz. de Tlalpan 3465, Sta. Úrsula Coapa, Coyoacán, 04650 Ciudad de México, CDMX, Mexico | D3: Mexico City | E3: Mexico | F3: 72766 | G3: =F3*(91/100)*(12/100) -> 7946.0472 | I3: =4.5/$H$2 -> 0.0625
A4: AT&T Stadium | B4: Dallas Stadium | C4: 1 AT&T Way, Arlington, TX 76011, USA | D4: Arlington | E4: USA | F4: 70122 | G4: =F4*(91/100)*(12/100) -> 7657.3224 | I4: =4.5/$H$2 -> 0.0625
A5: SoFi Stadium | B5: Los Angeles Stadium | C5: 1001 Stadium Dr, Inglewood, CA 90301, USA | D5: Inglewood | E5: USA | F5: 69650 | G5: =F5*(91/100)*(12/100) -> 7605.78 | I5: =4.5/$H$2 -> 0.0625
A6: Levi's Stadium | B6: San Francisco Bay Area Stadium | C6: 4900 Marie P DeBartolo Way, Santa Clara, CA 95054, USA | D6: Santa Clara | E6: USA | F6: 69391 | G6: =F6*(91/100)*(12/100) -> 7577.4972 | I6: =4.5/$H$2 -> 0.0625
A7: NRG Stadium | B7: Houston Stadium | C7: NRG Pkwy, Houston, TX 77054, USA | D7: Houston | E7: USA | F7: 68311 | G7: =F7*(91/100)*(12/100) -> 7459.5612 | I7: =4.5/$H$2 -> 0.0625
A8: GEHA Field at Arrowhead Stadium | B8: Kansas City Stadium | C8: 1 Arrowhead Dr, Kansas City, MO 64129, USA | D8: Kansas City | E8: USA | F8: 67513 | G8: =F8*(91/100)*(12/100) -> 7372.4196 | I8: =4.5/$H$2 -> 0.0625
A9: Mercedes-Benz Stadium | B9: Atlanta Stadium | C9: 1 AMB Dr NW, Atlanta, GA 30313, USA | D9: Atlanta | E9: USA | F9: 67382 | G9: =F9*(91/100)*(12/100) -> 7358.1144 | I9: =4.5/$H$2 -> 0.0625
A10: Lincoln Financial Field | B10: Philadelphia Stadium | C10: One Lincoln Financial Field Way, Philadelphia, PA 19148, USA | D10: Philadelphia | E10: USA | F10: 65827 | G10: =F10*(91/100)*(12/100) -> 7188.3084 | I10: =4.5/$H$2 -> 0.0625
A11: Lumen Field | B11: Seattle Stadium | C11: 800 Occidental Ave S, Seattle, WA 98134, USA | D11: Seattle | E11: USA | F11: 65123 | G11: =F11*(91/100)*(12/100) -> 7111.4316 | I11: =4.5/$H$2 -> 0.0625
A12: Hard Rock Stadium | B12: Miami Stadium | C12: 347 Don Shula Dr, Miami Gardens, FL 33056, USA | D12: Miami Gardens | E12: USA | F12: 64091 | G12: =F12*(91/100)*(12/100) -> 6998.7372 | I12: =4.5/$H$2 -> 0.0625
A13: Gillette Stadium | B13: Boston Stadium | C13: 1 Patriot Pl, Foxborough, MA 02035, USA | D13: Foxborough | E13: USA | F13: 63815 | G13: =F13*(91/100)*(12/100) -> 6968.598 | I13: =4.5/$H$2 -> 0.0625
A14: Estadio BBVA | B14: Monterrey Stadium | C14: Av. Pablo Livas 2011, colonia La Pastora, C.P. 67140, en Guadalupe, Nuevo León, Mexico | D14: Guadalupe | E14: Mexico | F14: 50113 | G14: =F14*(91/100)*(12/100) -> 5472.3396 | I14: =4.5/$H$2 -> 0.0625
... A17: BMO Field | B17: Toronto Stadium | C17: 170 Princes' Blvd, Toronto, ON M6K 3C3, Canada | D17: Toronto | E17: Canada | F17: 44315 | G17: =F17*(91/100)*(12/100) -> 4839.198 | I17: =4.5/$H$2 -> 0.0625

Sheet Confederation
A1: Team | B1: Confederation | C1: FIFA Points
A2: Spain | B2: UEFA | C2: 1877.18
A3: Argentina | B3: CONMEBOL | C3: 1873.33
A4: France | B4: UEFA | C4: 1870
A5: England | B5: UEFA | C5: 1834.12
A6: Brazil | B6: CONMEBOL | C6: 1760.46
A7: Portugal | B7: UEFA | C7: 1760.38
A8: Netherlands | B8: UEFA | C8: 1756.27
A9: Morocco | B9: CAF | C9: 1736.56
A10: Belgium | B10: UEFA | C10: 1730.71
A11: Germany | B11: UEFA | C11: 1724.15
A12: Croatia | B12: UEFA | C12: 1716.88
A13: Senegal | B13: CAF | C13: 1706.83
... A49: New Zealand | B49: OFC | C49: 1279.25

Sheet Results Q2
A1: Group 1:
A2: Pot 1 - Spain (1877.18)
A3: Pot 2 - Korea Republic (1599.45)
A4: Pot 3 - Paraguay (1501.5)
A5: Pot 4 - Cabo Verde (1370.49)
A6: Total Points: 6348.62
A8: Group 2:
A9: Pot 1 - Argentina (1873.33)
A10: Pot 2 - United States (USA) (1681.88)
A11: Pot 3 - Norway (1553.14)
A12: Pot 4 - New Zealand (1279.25)
A13: Total Points: 6387.6
... A85: Minimum Group Strength (w): 6341.67

Sheet Russia 2018 FIFA attendance
A1: Rank | B1: Country | C1: Confederations | D1: Available average attendance
A2: 1 | B2: Morocco | C2: CAF | D2: 62548
A3: 3 | B3: Germany | C3: UEFA | D3: 61149
A4: 4 | B4: Portugal | C4: UEFA | D4: 60939
A5: 5 | B5: Denmark | C5: UEFA | D5: 59369
A6: 6 | B6: Spain | C6: UEFA | D6: 55992
A7: 8 | B7: France | C7: UEFA | D7: 51848
A8: 9 | B8: Croatia | C8: UEFA | D8: 49999
A9: 11 | B9: Belgium | C9: UEFA | D9: 48330
A10: 12 | B10: Brazil | C10: CONMEBOL | D10: 48105
A11: 13 | B11: Australia | C11: AFC | D11: 44073
A12: 14 | B12: Argentina | C12: CONMEBOL | D12: 43754
A13: 17 | B13: Switzerland | C13: UEFA | D13: 43319
... A25: 32 | B25: Egypt | C25: CAF | D25: 27015

Sheet GDP
A1: Country | B1: Capital_city | C1: GDP_worldbank (2024) ($) | D1: distance_to_host_min_km | E1: nearest_host_capital | F1: distance_to_washington_km | G1: distance_to_ottawa_km | H1: distance_to_mexico_city_km | I1: diaspora_us_2024 | J1: diaspora_ca_2021 | K1: diaspora_mx_2024 | L1: diaspora_total | M1: dist_adj | N1: inv_dist | O1: gdp_norm | P1: inv_dist_norm | Q1: diaspora_norm（min-max） | R1: g_i (proxy)
A2: Switzerland | B2: Bern | C2: 103998.19 | D2: 6083.9 | E2: Ottawa | F2: 6598.1 | G2: 6083.9 | H2: 9629.1 | I2: 38004 | J2: 18185 | K2: 1439 | L2: =IFERROR(VALUE(I2),0)+IFERROR(VALUE(J2),0)+IFERROR(VALUE(K2),0) -> 57628 | M2: =MAX(D2, 1) -> 6083.9 | N2: =1/M2 -> 0.00016436825 | O2: =(C2-MIN($C:$C))/(MAX($C:$C)-MIN($C:$C)) -> 1 | P2: =(N2-MIN($N:$N))/(MAX($N:$N)-MIN($N:$N)) -> 8.8503007e-05 | Q2: =(L2-MIN($L:$L))/(MAX($L:$L)-MIN($L:$L)) -> 0.0050937827 | R2: =0.4*O2+0.3*P2+0.3*Q2 -> 0.40155469
A3: Norway | B3: Oslo | C3: 86785.433 | D3: 5597.9 | E3: Ottawa | F3: 6231.6 | G3: 5597.9 | H3: 9195.1 | I3: 19842 | J3: 3845 | K3: NA | L3: =IFERROR(VALUE(I3),0)+IFERROR(VALUE(J3),0)+IFERROR(VALUE(K3),0) -> 23687 | M3: =MAX(D3, 1) -> 5597.9 | N3: =1/M3 -> 0.00017863842 | O3: =(C3-MIN($C:$C))/(MAX($C:$C)-MIN($C:$C)) -> 0.8334499 | P3: =(N3-MIN($N:$N))/(MAX($N:$N)-MIN($N:$N)) -> 0.00010277426 | Q3: =(L3-MIN($L:$L))/(MAX($L:$L)-MIN($L:$L)) -> 0.0020724787 | R3: =0.4*O3+0.3*P3+0.3*Q3 -> 0.33403254
A4: USA | B4: Washington, D.C. | C4: 84534.041 | D4: 0 | E4: Washington, D.C. | F4: 0 | G4: 732.7 | H4: 3031.8 | I4: 0 | J4: 256090 | K4: 797266 | L4: =IFERROR(VALUE(I4),0)+IFERROR(VALUE(J4),0)+IFERROR(VALUE(K4),0) -> 1053356 | M4: =MAX(D4, 1) -> 1 | N4: =1/M4 -> 1 | O4: =(C4-MIN($C:$C))/(MAX($C:$C)-MIN($C:$C)) -> 0.81166549 | P4: =(N4-MIN($N:$N))/(MAX($N:$N)-MIN($N:$N)) -> 1 | Q4: =(L4-MIN($L:$L))/(MAX($L:$L)-MIN($L:$L)) -> 0.093729857 | R4: =0.4*O4+0.3*P4+0.3*Q4 -> 0.65278515
A5: Qatar | B5: Doha | C5: 76688.694 | D5: 10515.7 | E5: Ottawa | F5: 11098.2 | G5: 10515.7 | H5: 14116.8 | I5: NA | J5: 4110 | K5: NA | L5: =IFERROR(VALUE(I5),0)+IFERROR(VALUE(J5),0)+IFERROR(VALUE(K5),0) -> 4110 | M5: =MAX(D5, 1) -> 10515.7 | N5: =1/M5 -> 9.5095904e-05 | O5: =(C5-MIN($C:$C))/(MAX($C:$C)-MIN($C:$C)) -> 0.73575415 | P5: =(N5-MIN($N:$N))/(MAX($N:$N)-MIN($N:$N)) -> 1.9225404e-05 | Q5: =(L5-MIN($L:$L))/(MAX($L:$L)-MIN($L:$L)) -> 0.00032980559 | R5: =0.4*O5+0.3*P5+0.3*Q5 -> 0.29440637
A6: Denmark | B6: Copenhagen | C6: 71026.483 | D6: 5905.5 | E6: Ottawa | F6: 6510.4 | G6: 5905.5 | H6: 9508.8 | I6: 25182 | J6: 11000 | K6: NA | L6: =IFERROR(VALUE(I6),0)+IFERROR(VALUE(J6),0)+IFERROR(VALUE(K6),0) -> 36182 | M6: =MAX(D6, 1) -> 5905.5 | N6: =1/M6 -> 0.00016933367 | O6: =(C6-MIN($C:$C))/(MAX($C:$C)-MIN($C:$C)) -> 0.68096676 | P6: =(N6-MIN($N:$N))/(MAX($N:$N)-MIN($N:$N)) -> 9.3468805e-05 | Q6: =(L6-MIN($L:$L))/(MAX($L:$L)-MIN($L:$L)) -> 0.003184738 | R6: =0.4*O6+0.3*P6+0.3*Q6 -> 0.27337017
A7: Netherlands | B7: Amsterdam | C7: 67520.422 | D7: 5630.9 | E7: Ottawa | F7: 6189 | G7: 5630.9 | H7: 9215.8 | I7: 74774 | J7: 75830 | K7: NA | L7: =IFERROR(VALUE(I7),0)+IFERROR(VALUE(J7),0)+IFERROR(VALUE(K7),0) -> 150604 | M7: =MAX(D7, 1) -> 5630.9 | N7: =1/M7 -> 0.0001775915 | O7: =(C7-MIN($C:$C))/(MAX($C:$C)-MIN($C:$C)) -> 0.64704221 | P7: =(N7-MIN($N:$N))/(MAX($N:$N)-MIN($N:$N)) -> 0.00010172726 | Q7: =(L7-MIN($L:$L))/(MAX($L:$L)-MIN($L:$L)) -> 0.013370167 | R7: =0.4*O7+0.3*P7+0.3*Q7 -> 0.26285845
A8: Australia | B8: Canberra | C8: 64603.986 | D8: 13180.1 | E8: Mexico City | F8: 15947.2 | G8: 16111.3 | H8: 13180.1 | I8: 112037 | J8: 25200 | K8: NA | L8: =IFERROR(VALUE(I8),0)+IFERROR(VALUE(J8),0)+IFERROR(VALUE(K8),0) -> 137237 | M8: =MAX(D8, 1) -> 13180.1 | N8: =1/M8 -> 7.5871958e-05 | O8: =(C8-MIN($C:$C))/(MAX($C:$C)-MIN($C:$C)) -> 0.61882286 | P8: =(N8-MIN($N:$N))/(MAX($N:$N)-MIN($N:$N)) -> 0 | Q8: =(L8-MIN($L:$L))/(MAX($L:$L)-MIN($L:$L)) -> 0.012180286 | R8: =0.4*O8+0.3*P8+0.3*Q8 -> 0.25118323
A9: Austria | B9: Vienna | C9: 58268.879 | D9: 6567 | E9: Ottawa | F9: 7123.2 | G9: 6567 | H9: 10151.3 | I9: 37622 | J9: 13840 | K9: NA | L9: =IFERROR(VALUE(I9),0)+IFERROR(VALUE(J9),0)+IFERROR(VALUE(K9),0) -> 51462 | M9: =MAX(D9, 1) -> 6567 | N9: =1/M9 -> 0.00015227653 | O9: =(C9-MIN($C:$C))/(MAX($C:$C)-MIN($C:$C)) -> 0.55752455 | P9: =(N9-MIN($N:$N))/(MAX($N:$N)-MIN($N:$N)) -> 7.6410373e-05 | Q9: =(L9-MIN($L:$L))/(MAX($L:$L)-MIN($L:$L)) -> 0.0045449079 | R9: =0.4*O9+0.3*P9+0.3*Q9 -> 0.22439622
A10: Belgium | B10: Brussels | C10: 56614.568 | D10: 5674.1 | E10: Ottawa | F10: 6216.1 | G10: 5674.1 | H10: 9246.7 | I10: 38468 | J10: 18650 | K10: NA | L10: =IFERROR(VALUE(I10),0)+IFERROR(VALUE(J10),0)+IFERROR(VALUE(K10),0) -> 57118 | M10: =MAX(D10, 1) -> 5674.1 | N10: =1/M10 -> 0.0001762394 | O10: =(C10-MIN($C:$C))/(MAX($C:$C)-MIN($C:$C)) -> 0.54151749 | P10: =(N10-MIN($N:$N))/(MAX($N:$N)-MIN($N:$N)) -> 0.00010037506 | Q10: =(L10-MIN($L:$L))/(MAX($L:$L)-MIN($L:$L)) -> 0.0050483844 | R10: =0.4*O10+0.3*P10+0.3*Q10 -> 0.21815162
A11: Germany | B11: Berlin | C11: 56103.732 | D11: 6127.7 | E11: Ottawa | F11: 6709.4 | G11: 6127.7 | H11: 9725.9 | I11: 519159 | J11: 126470 | K11: 6860 | L11: =IFERROR(VALUE(I11),0)+IFERROR(VALUE(J11),0)+IFERROR(VALUE(K11),0) -> 652489 | M11: =MAX(D11, 1) -> 6127.7 | N11: =1/M11 -> 0.00016319337 | O11: =(C11-MIN($C:$C))/(MAX($C:$C)-MIN($C:$C)) -> 0.53657466 | P11: =(N11-MIN($N:$N))/(MAX($N:$N)-MIN($N:$N)) -> 8.7328035e-05 | Q11: =(L11-MIN($L:$L))/(MAX($L:$L)-MIN($L:$L)) -> 0.058046139 | R11: =0.4*O11+0.3*P11+0.3*Q11 -> 0.2320699
A12: Canada | B12: Ottawa | C12: 54340.348 | D12: 0 | E12: Ottawa | F12: 732.7 | G12: 0 | H12: 3603.7 | I12: 823843 | J12: 0 | K12: 12439 | L12: =IFERROR(VALUE(I12),0)+IFERROR(VALUE(J12),0)+IFERROR(VALUE(K12),0) -> 836282 | M12: =MAX(D12, 1) -> 1 | N12: =1/M12 -> 1 | O12: =(C12-MIN($C:$C))/(MAX($C:$C)-MIN($C:$C)) -> 0.5195122 | P12: =(N12-MIN($N:$N))/(MAX($N:$N)-MIN($N:$N)) -> 1 | Q12: =(L12-MIN($L:$L))/(MAX($L:$L)-MIN($L:$L)) -> 0.074406722 | R12: =0.4*O12+0.3*P12+0.3*Q12 -> 0.5301269
A13: Scotland | B13: Edinburgh | C13: 53246.368 | D13: 4993 | E13: Ottawa | F13: 5569.7 | G13: 4993 | H13: 8587.9 | I13: 53356 | J13: NA | K13: 4030 | L13: =IFERROR(VALUE(I13),0)+IFERROR(VALUE(J13),0)+IFERROR(VALUE(K13),0) -> 57386 | M13: =MAX(D13, 1) -> 4993 | N13: =1/M13 -> 0.00020028039 | O13: =(C13-MIN($C:$C))/(MAX($C:$C)-MIN($C:$C)) -> 0.50892688 | P13: =(N13-MIN($N:$N))/(MAX($N:$N)-MIN($N:$N)) -> 0.00012441787 | Q13: =(L13-MIN($L:$L))/(MAX($L:$L)-MIN($L:$L)) -> 0.0050722408 | R13: =0.4*O13+0.3*P13+0.3*Q13 -> 0.20512975
A14: England | B14: London | C14: 53246.368 | D14: 5361 | E14: Ottawa | F14: 5897.6 | G14: 5361 | H14: 8928.7 | I14: 298535 | J14: 464135 | K14: 4030 | L14: =IFERROR(VALUE(I14),0)+IFERROR(VALUE(J14),0)+IFERROR(VALUE(K14),0) -> 766700 | M14: =MAX(D14, 1) -> 5361 | N14: =1/M14 -> 0.00018653236 | O14: =(C14-MIN($C:$C))/(MAX($C:$C)-MIN($C:$C)) -> 0.50892688 | P14: =(N14-MIN($N:$N))/(MAX($N:$N)-MIN($N:$N)) -> 0.0001106688 | Q14: =(L14-MIN($L:$L))/(MAX($L:$L)-MIN($L:$L)) -> 0.068212786 | R14: =0.4*O14+0.3*P14+0.3*Q14 -> 0.22406779
A15: New Zealand | B15: Wellington | C15: 49205.179 | D15: 11103.7 | E15: Mexico City | F15: 14082.8 | G15: 14484.4 | H15: 11103.7 | I15: NA | J15: 10675 | K15: NA | L15: =IFERROR(VALUE(I15),0)+IFERROR(VALUE(J15),0)+IFERROR(VALUE(K15),0) -> 10675 | M15: =MAX(D15, 1) -> 11103.7 | N15: =1/M15 -> 9.006007e-05 | O15: =(C15-MIN($C:$C))/(MAX($C:$C)-MIN($C:$C)) -> 0.46982446 | P15: =(N15-MIN($N:$N))/(MAX($N:$N)-MIN($N:$N)) -> 1.4189188e-05 | Q15: =(L15-MIN($L:$L))/(MAX($L:$L)-MIN($L:$L)) -> 0.00091419794 | R15: =0.4*O15+0.3*P15+0.3*Q15 -> 0.1882083
A16: France | B16: Paris | C16: 46103.084 | D16: 5648.7 | E16: Ottawa | F16: 6164.8 | G16: 5648.7 | H16: 9196.2 | I16: 179804 | J16: 121525 | K16: 9080 | L16: =IFERROR(VALUE(I16),0)+IFERROR(VALUE(J16),0)+IFERROR(VALUE(K16),0) -> 310409 | M16: =MAX(D16, 1) -> 5648.7 | N16: =1/M16 -> 0.00017703188 | O16: =(C16-MIN($C:$C))/(MAX($C:$C)-MIN($C:$C)) -> 0.43980868 | P16: =(N16-MIN($N:$N))/(MAX($N:$N)-MIN($N:$N)) -> 0.0001011676 | Q16: =(L16-MIN($L:$L))/(MAX($L:$L)-MIN($L:$L)) -> 0.027595425 | R16: =0.4*O16+0.3*P16+0.3*Q16 -> 0.18423245
A17: Italy | B17: Rome | C17: 40385.341 | D17: 6728.8 | E17: Ottawa | F17: 7216.3 | G17: 6728.8 | H17: 10239.8 | I17: 284510 | J17: 204065 | K17: 6619 | L17: =IFERROR(VALUE(I17),0)+IFERROR(VALUE(J17),0)+IFERROR(VALUE(K17),0) -> 495194 | M17: =MAX(D17, 1) -> 6728.8 | N17: =1/M17 -> 0.00014861491 | O17: =(C17-MIN($C:$C))/(MAX($C:$C)-MIN($C:$C)) -> 0.38448397 | P17: =(N17-MIN($N:$N))/(MAX($N:$N)-MIN($N:$N)) -> 7.274847e-05 | Q17: =(L17-MIN($L:$L))/(MAX($L:$L)-MIN($L:$L)) -> 0.044044312 | R17: =0.4*O17+0.3*P17+0.3*Q17 -> 0.16702871
A18: Korea Republic | B18: Seoul | C18: 36238.64 | D18: 10511.9 | E18: Ottawa | F18: 11163.9 | G18: 10511.9 | H18: 12051.7 | I18: 1087657 | J18: 138355 | K18: 5339 | L18: =IFERROR(VALUE(I18),0)+IFERROR(VALUE(J18),0)+IFERROR(VALUE(K18),0) -> 1231351 | M18: =MAX(D18, 1) -> 10511.9 | N18: =1/M18 -> 9.5130281e-05 | O18: =(C18-MIN($C:$C))/(MAX($C:$C)-MIN($C:$C)) -> 0.34436061 | P18: =(N18-MIN($N:$N))/(MAX($N:$N)-MIN($N:$N)) -> 1.9259784e-05 | Q18: =(L18-MIN($L:$L))/(MAX($L:$L)-MIN($L:$L)) -> 0.10957432 | R18: =0.4*O18+0.3*P18+0.3*Q18 -> 0.17062232
A19: Spain | B19: Madrid | C19: 35326.768 | D19: 5690 | E19: Ottawa | F19: 6088.2 | G19: 5690 | H19: 9062.7 | I19: 136202 | J19: 11510 | K19: 20763 | L19: =IFERROR(VALUE(I19),0)+IFERROR(VALUE(J19),0)+IFERROR(VALUE(K19),0) -> 168475 | M19: =MAX(D19, 1) -> 5690 | N19: =1/M19 -> 0.00017574692 | O19: =(C19-MIN($C:$C))/(MAX($C:$C)-MIN($C:$C)) -> 0.33553736 | P19: =(N19-MIN($N:$N))/(MAX($N:$N)-MIN($N:$N)) -> 9.9882544e-05 | Q19: =(L19-MIN($L:$L))/(MAX($L:$L)-MIN($L:$L)) -> 0.014960978 | R19: =0.4*O19+0.3*P19+0.3*Q19 -> 0.1387332
A20: Saudi Arabia | B20: Riyadh | C20: 35121.663 | D20: 10295 | E20: Ottawa | F20: 10846.1 | G20: 10295 | H20: 13877.3 | I20: 59727 | J20: 29585 | K20: NA | L20: =IFERROR(VALUE(I20),0)+IFERROR(VALUE(J20),0)+IFERROR(VALUE(K20),0) -> 89312 | M20: =MAX(D20, 1) -> 10295 | N20: =1/M20 -> 9.7134531e-05 | O20: =(C20-MIN($C:$C))/(MAX($C:$C)-MIN($C:$C)) -> 0.33355277 | P20: =(N20-MIN($N:$N))/(MAX($N:$N)-MIN($N:$N)) -> 2.1264186e-05 | Q20: =(L20-MIN($L:$L))/(MAX($L:$L)-MIN($L:$L)) -> 0.0079141768 | R20: =0.4*O20+0.3*P20+0.3*Q20 -> 0.13580174
A21: Japan | B21: Tokyo | C21: 32487.078 | D21: 10319.3 | E21: Ottawa | F21: 10901.1 | G21: 10319.3 | H21: 11301.3 | I21: 342968 | J21: 30870 | K21: 5539 | L21: =IFERROR(VALUE(I21),0)+IFERROR(VALUE(J21),0)+IFERROR(VALUE(K21),0) -> 379377 | M21: =MAX(D21, 1) -> 10319.3 | N21: =1/M21 -> 9.6905798e-05 | O21: =(C21-MIN($C:$C))/(MAX($C:$C)-MIN($C:$C)) -> 0.3080606 | P21: =(N21-MIN($N:$N))/(MAX($N:$N)-MIN($N:$N)) -> 2.1035435e-05 | Q21: =(L21-MIN($L:$L))/(MAX($L:$L)-MIN($L:$L)) -> 0.033734705 | R21: =0.4*O21+0.3*P21+0.3*Q21 -> 0.13335096
A22: Portugal | B22: Lisbon | C22: 29292.242 | D22: 5387.2 | E22: Ottawa | F22: 5737.2 | G22: 5387.2 | H22: 8672 | I22: 150049 | J22: 128795 | K22: NA | L22: =IFERROR(VALUE(I22),0)+IFERROR(VALUE(J22),0)+IFERROR(VALUE(K22),0) -> 278844 | M22: =MAX(D22, 1) -> 5387.2 | N22: =1/M22 -> 0.00018562519 | O22: =(C22-MIN($C:$C))/(MAX($C:$C)-MIN($C:$C)) -> 0.27714746 | P22: =(N22-MIN($N:$N))/(MAX($N:$N)-MIN($N:$N)) -> 0.00010976155 | Q22: =(L22-MIN($L:$L))/(MAX($L:$L)-MIN($L:$L)) -> 0.024785624 | R22: =0.4*O22+0.3*P22+0.3*Q22 -> 0.1183276
A23: Croatia | B23: Zagreb | C23: 24050.44 | D23: 6697.7 | E23: Ottawa | F23: 7233.1 | G23: 6697.7 | H23: 10264.8 | I23: 40180 | J23: 36675 | K23: NA | L23: =IFERROR(VALUE(I23),0)+IFERROR(VALUE(J23),0)+IFERROR(VALUE(K23),0) -> 76855 | M23: =MAX(D23, 1) -> 6697.7 | N23: =1/M23 -> 0.00014930499 | O23: =(C23-MIN($C:$C))/(MAX($C:$C)-MIN($C:$C)) -> 0.22642794 | P23: =(N23-MIN($N:$N))/(MAX($N:$N)-MIN($N:$N)) -> 7.3438599e-05 | Q23: =(L23-MIN($L:$L))/(MAX($L:$L)-MIN($L:$L)) -> 0.0068053001 | R23: =0.4*O23+0.3*P23+0.3*Q23 -> 0.092634797
A24: Uruguay | B24: Montevideo | C24: 23906.513 | D24: 7553.3 | E24: Mexico City | F24: 8483.1 | G24: 9145 | H24: 7553.3 | I24: 55742 | J24: 6435 | K24: 2706 | L24: =IFERROR(VALUE(I24),0)+IFERROR(VALUE(J24),0)+IFERROR(VALUE(K24),0) -> 64883 | M24: =MAX(D24, 1) -> 7553.3 | N24: =1/M24 -> 0.00013239246 | O24: =(C24-MIN($C:$C))/(MAX($C:$C)-MIN($C:$C)) -> 0.22503531 | P24: =(N24-MIN($N:$N))/(MAX($N:$N)-MIN($N:$N)) -> 5.6524794e-05 | Q24: =(L24-MIN($L:$L))/(MAX($L:$L)-MIN($L:$L)) -> 0.0057395964 | R24: =0.4*O24+0.3*P24+0.3*Q24 -> 0.09175296
A25: Curaçao | B25: Willemstad | C25: 22832.895 | D25: 3085.3 | E25: Washington, D.C. | F25: 3085.3 | G25: 3758.6 | H25: 3332.1 | I25: NA | J25: 405 | K25: NA | L25: =IFERROR(VALUE(I25),0)+IFERROR(VALUE(J25),0)+IFERROR(VALUE(K25),0) -> 405 | M25: =MAX(D25, 1) -> 3085.3 | N25: =1/M25 -> 0.00032411759 | O25: =(C25-MIN($C:$C))/(MAX($C:$C)-MIN($C:$C)) -> 0.21464701 | P25: =(N25-MIN($N:$N))/(MAX($N:$N)-MIN($N:$N)) -> 0.00024826447 | Q25: =(L25-MIN($L:$L))/(MAX($L:$L)-MIN($L:$L)) -> 0 | R25: =0.4*O25+0.3*P25+0.3*Q25 -> 0.085933285
A26: Panama | B26: Panama City | C26: 19161.219 | D26: 2408.1 | E26: Mexico City | F26: 3338 | G26: 4069.7 | H26: 2408.1 | I26: 107163 | J26: 2800 | K26: 1916 | L26: =IFERROR(VALUE(I26),0)+IFERROR(VALUE(J26),0)+IFERROR(VALUE(K26),0) -> 111879 | M26: =MAX(D26, 1) -> 2408.1 | N26: =1/M26 -> 0.00041526515 | O26: =(C26-MIN($C:$C))/(MAX($C:$C)-MIN($C:$C)) -> 0.17911998 | P26: =(N26-MIN($N:$N))/(MAX($N:$N)-MIN($N:$N)) -> 0.00033941894 | Q26: =(L26-MIN($L:$L))/(MAX($L:$L)-MIN($L:$L)) -> 0.0099230089 | R26: =0.4*O26+0.3*P26+0.3*Q26 -> 0.07472672
A27: Turkiye | B27: Ankara | C27: 15892.716 | D27: 8160.1 | E27: Ottawa | F27: 8724.2 | G27: 8160.1 | H27: 11750.9 | I27: 184010 | J27: 35270 | K27: NA | L27: =IFERROR(VALUE(I27),0)+IFERROR(VALUE(J27),0)+IFERROR(VALUE(K27),0) -> 219280 | M27: =MAX(D27, 1) -> 8160.1 | N27: =1/M27 -> 0.00012254752 | O27: =(C27-MIN($C:$C))/(MAX($C:$C)-MIN($C:$C)) -> 0.14749404 | P27: =(N27-MIN($N:$N))/(MAX($N:$N)-MIN($N:$N)) -> 4.6679101e-05 | Q27: =(L27-MIN($L:$L))/(MAX($L:$L)-MIN($L:$L)) -> 0.019483454 | R27: =0.4*O27+0.3*P27+0.3*Q27 -> 0.064856655
A28: Mexico | B28: Mexico City | C28: 14185.781 | D28: 0 | E28: Mexico City | F28: 3031.8 | G28: 3603.3 | H28: 0 | I28: 11143711 | J28: 90585 | K28: NA | L28: =IFERROR(VALUE(I28),0)+IFERROR(VALUE(J28),0)+IFERROR(VALUE(K28),0) -> 11234296 | M28: =MAX(D28, 1) -> 1 | N28: =1/M28 -> 1 | O28: =(C28-MIN($C:$C))/(MAX($C:$C)-MIN($C:$C)) -> 0.13097779 | P28: =(N28-MIN($N:$N))/(MAX($N:$N)-MIN($N:$N)) -> 1 | Q28: =(L28-MIN($L:$L))/(MAX($L:$L)-MIN($L:$L)) -> 1 | R28: =0.4*O28+0.3*P28+0.3*Q28 -> 0.65239112
A29: Argentina | B29: Buenos Aires | C29: 13969.784 | D29: 7389.1 | E29: Mexico City | F29: 8395.7 | G29: 9066.8 | H29: 7389.1 | I29: 210909 | J29: 19530 | K29: 18693 | L29: =IFERROR(VALUE(I29),0)+IFERROR(VALUE(J29),0)+IFERROR(VALUE(K29),0) -> 249132 | M29: =MAX(D29, 1) -> 7389.1 | N29: =1/M29 -> 0.00013533448 | O29: =(C29-MIN($C:$C))/(MAX($C:$C)-MIN($C:$C)) -> 0.1288878 | P29: =(N29-MIN($N:$N))/(MAX($N:$N)-MIN($N:$N)) -> 5.9467033e-05 | Q29: =(L29-MIN($L:$L))/(MAX($L:$L)-MIN($L:$L)) -> 0.02214077 | R29: =0.4*O29+0.3*P29+0.3*Q29 -> 0.058215193
A30: Brazil | B30: Brasília | C30: 10310.549 | D30: 6796.2 | E30: Washington, D.C. | F30: 6796.2 | G30: 7361.5 | H30: 6836.6 | I30: 725419 | J30: 48450 | K30: 8689 | L30: =IFERROR(VALUE(I30),0)+IFERROR(VALUE(J30),0)+IFERROR(VALUE(K30),0) -> 782558 | M30: =MAX(D30, 1) -> 6796.2 | N30: =1/M30 -> 0.00014714105 | O30: =(C30-MIN($C:$C))/(MAX($C:$C)-MIN($C:$C)) -> 0.093481155 | P30: =(N30-MIN($N:$N))/(MAX($N:$N)-MIN($N:$N)) -> 7.1274499e-05 | Q30: =(L30-MIN($L:$L))/(MAX($L:$L)-MIN($L:$L)) -> 0.069624407 | R30: =0.4*O30+0.3*P30+0.3*Q30 -> 0.058301167
A31: Colombia | B31: Bogotá | C31: 7919.2089 | D31: 3177.3 | E31: Mexico City | F31: 3826.7 | G31: 4542.1 | H31: 3177.3 | I31: 1153648 | J31: 80570 | K31: 36234 | L31: =IFERROR(VALUE(I31),0)+IFERROR(VALUE(J31),0)+IFERROR(VALUE(K31),0) -> 1270452 | M31: =MAX(D31, 1) -> 3177.3 | N31: =1/M31 -> 0.00031473263 | O31: =(C31-MIN($C:$C))/(MAX($C:$C)-MIN($C:$C)) -> 0.070342619 | P31: =(N31-MIN($N:$N))/(MAX($N:$N)-MIN($N:$N)) -> 0.0002388788 | Q31: =(L31-MIN($L:$L))/(MAX($L:$L)-MIN($L:$L)) -> 0.11305495 | R31: =0.4*O31+0.3*P31+0.3*Q31 -> 0.062125197
A32: Ecuador | B32: Quito | C32: 6874.7057 | D32: 3135.3 | E32: Mexico City | F32: 4353.4 | G32: 5082.7 | H32: 3135.3 | I32: 621915 | J32: 16320 | K32: 3995 | L32: =IFERROR(VALUE(I32),0)+IFERROR(VALUE(J32),0)+IFERROR(VALUE(K32),0) -> 642230 | M32: =MAX(D32, 1) -> 3135.3 | N32: =1/M32 -> 0.00031894874 | O32: =(C32-MIN($C:$C))/(MAX($C:$C)-MIN($C:$C)) -> 0.060236038 | P32: =(N32-MIN($N:$N))/(MAX($N:$N)-MIN($N:$N)) -> 0.00024309523 | Q32: =(L32-MIN($L:$L))/(MAX($L:$L)-MIN($L:$L)) -> 0.05713292 | R32: =0.4*O32+0.3*P32+0.3*Q32 -> 0.04130722
A33: Paraguay | B33: Asunción | C33: 6416.0971 | D33: 6696.8 | E33: Mexico City | F33: 7417.2 | G33: 8071.6 | H33: 6696.8 | I33: NA | J33: 6085 | K33: NA | L33: =IFERROR(VALUE(I33),0)+IFERROR(VALUE(J33),0)+IFERROR(VALUE(K33),0) -> 6085 | M33: =MAX(D33, 1) -> 6696.8 | N33: =1/M33 -> 0.00014932505 | O33: =(C33-MIN($C:$C))/(MAX($C:$C)-MIN($C:$C)) -> 0.055798554 | P33: =(N33-MIN($N:$N))/(MAX($N:$N)-MIN($N:$N)) -> 7.3458666e-05 | Q33: =(L33-MIN($L:$L))/(MAX($L:$L)-MIN($L:$L)) -> 0.00050561288 | R33: =0.4*O33+0.3*P33+0.3*Q33 -> 0.022493143
A34: South Africa | B34: Pretoria | C34: 6267.1868 | D34: 13030.5 | E34: Washington, D.C. | F34: 13030.5 | G34: 13060.9 | H34: 14595.7 | I34: 156094 | J34: 51590 | K34: NA | L34: =IFERROR(VALUE(I34),0)+IFERROR(VALUE(J34),0)+IFERROR(VALUE(K34),0) -> 207684 | M34: =MAX(D34, 1) -> 13030.5 | N34: =1/M34 -> 7.6743026e-05 | O34: =(C34-MIN($C:$C))/(MAX($C:$C)-MIN($C:$C)) -> 0.054357702 | P34: =(N34-MIN($N:$N))/(MAX($N:$N)-MIN($N:$N)) -> 8.7113359e-07 | Q34: =(L34-MIN($L:$L))/(MAX($L:$L)-MIN($L:$L)) -> 0.018451221 | R34: =0.4*O34+0.3*P34+0.3*Q34 -> 0.027278708
A35: Iraq | B35: Sucre | C35: 6073.61 | D35: 5652.9 | E35: Mexico City | F35: 6560 | G35: 7246 | H35: 5652.9 | I35: 90698 | J35: 3835 | K35: 2505 | L35: =IFERROR(VALUE(I35),0)+IFERROR(VALUE(J35),0)+IFERROR(VALUE(K35),0) -> 97038 | M35: =MAX(D35, 1) -> 5652.9 | N35: =1/M35 -> 0.00017690035 | O35: =(C35-MIN($C:$C))/(MAX($C:$C)-MIN($C:$C)) -> 0.052484659 | P35: =(N35-MIN($N:$N))/(MAX($N:$N)-MIN($N:$N)) -> 0.00010103606 | Q35: =(L35-MIN($L:$L))/(MAX($L:$L)-MIN($L:$L)) -> 0.0086019172 | R35: =0.4*O35+0.3*P35+0.3*Q35 -> 0.023604749
A36: Algeria | B36: Algiers | C36: 5752.9908 | D36: 6403.2 | E36: Ottawa | F36: 6794.6 | G36: 6403.2 | H36: 9755 | I36: 36031 | J36: 79660 | K36: NA | L36: =IFERROR(VALUE(I36),0)+IFERROR(VALUE(J36),0)+IFERROR(VALUE(K36),0) -> 115691 | M36: =MAX(D36, 1) -> 6403.2 | N36: =1/M36 -> 0.00015617191 | O36: =(C36-MIN($C:$C))/(MAX($C:$C)-MIN($C:$C)) -> 0.049382356 | P36: =(N36-MIN($N:$N))/(MAX($N:$N)-MIN($N:$N)) -> 8.0306049e-05 | Q36: =(L36-MIN($L:$L))/(MAX($L:$L)-MIN($L:$L)) -> 0.010262339 | R36: =0.4*O36+0.3*P36+0.3*Q36 -> 0.022855736
A37: Ukraine | B37: Kiev | C37: 5389.4731 | D37: 7215.3 | E37: Ottawa | F37: 7832.7 | G37: 7215.3 | H37: 10816.9 | I37: 510016 | J37: 81135 | K37: NA | L37: =IFERROR(VALUE(I37),0)+IFERROR(VALUE(J37),0)+IFERROR(VALUE(K37),0) -> 591151 | M37: =MAX(D37, 1) -> 7215.3 | N37: =1/M37 -> 0.00013859438 | O37: =(C37-MIN($C:$C))/(MAX($C:$C)-MIN($C:$C)) -> 0.04586497 | P37: =(N37-MIN($N:$N))/(MAX($N:$N)-MIN($N:$N)) -> 6.2727177e-05 | Q37: =(L37-MIN($L:$L))/(MAX($L:$L)-MIN($L:$L)) -> 0.052586054 | R37: =0.4*O37+0.3*P37+0.3*Q37 -> 0.034140623
A38: Cabo Verde | B38: Praia | C38: 5192.4816 | D38: 5837.2 | E38: Washington, D.C. | F38: 5837.2 | G38: 5912.9 | H38: 7985.9 | I38: 47699 | J38: 250 | K38: NA | L38: =IFERROR(VALUE(I38),0)+IFERROR(VALUE(J38),0)+IFERROR(VALUE(K38),0) -> 47949 | M38: =MAX(D38, 1) -> 5837.2 | N38: =1/M38 -> 0.00017131501 | O38: =(C38-MIN($C:$C))/(MAX($C:$C)-MIN($C:$C)) -> 0.043958886 | P38: =(N38-MIN($N:$N))/(MAX($N:$N)-MIN($N:$N)) -> 9.5450298e-05 | Q38: =(L38-MIN($L:$L))/(MAX($L:$L)-MIN($L:$L)) -> 0.0042321935 | R38: =0.4*O38+0.3*P38+0.3*Q38 -> 0.018881847
A39: Iran | B39: Tehran | C39: 5190.1696 | D39: 9549.8 | E39: Ottawa | F39: 10175.8 | G39: 9549.8 | H39: 13144.2 | I39: 420227 | J39: 182940 | K39: NA | L39: =IFERROR(VALUE(I39),0)+IFERROR(VALUE(J39),0)+IFERROR(VALUE(K39),0) -> 603167 | M39: =MAX(D39, 1) -> 9549.8 | N39: =1/M39 -> 0.00010471423 | O39: =(C39-MIN($C:$C))/(MAX($C:$C)-MIN($C:$C)) -> 0.043936515 | P39: =(N39-MIN($N:$N))/(MAX($N:$N)-MIN($N:$N)) -> 2.8844465e-05 | Q39: =(L39-MIN($L:$L))/(MAX($L:$L)-MIN($L:$L)) -> 0.053655675 | R39: =0.4*O39+0.3*P39+0.3*Q39 -> 0.033679962
A40: Jordan | B40: Amman | C40: 4618.0959 | D40: 8999.9 | E40: Ottawa | F40: 9530.6 | G40: 8999.9 | H40: 12562 | I40: 91008 | J40: 17530 | K40: NA | L40: =IFERROR(VALUE(I40),0)+IFERROR(VALUE(J40),0)+IFERROR(VALUE(K40),0) -> 108538 | M40: =MAX(D40, 1) -> 8999.9 | N40: =1/M40 -> 0.00011111235 | O40: =(C40-MIN($C:$C))/(MAX($C:$C)-MIN($C:$C)) -> 0.038401147 | P40: =(N40-MIN($N:$N))/(MAX($N:$N)-MIN($N:$N)) -> 3.5243061e-05 | Q40: =(L40-MIN($L:$L))/(MAX($L:$L)-MIN($L:$L)) -> 0.0096256052 | R40: =0.4*O40+0.3*P40+0.3*Q40 -> 0.018258713
...

Sheet Missing country attendance
A1: Country (A) | B1: GDP_A_worldbank (2024) ($) | C1: Confederation | D1: Total attendance (A) | E1: Nearest Country (B) from the same confederation | F1: GDP_B_worldbank (2024) ($) | G1: Total attendance (B)
A2: Uzbekistan | B2: =VLOOKUP(A2, GDP!A:C, 3, FALSE) -> 3161.7001 | C2: AFC | D2: =G2*(B2/F2) -> 25708.229 | E2: Iran | F2: =VLOOKUP(E2, GDP!A:C, 3, FALSE) -> 5190.1696 | G2: =VLOOKUP(E2,'Russia 2018 FIFA attendance'!B:D,3,FALSE) -> 42202
A3: Qatar | B3: =VLOOKUP(A3, GDP!A:C, 3, FALSE) -> 76688.694 | C3: AFC | D3: =G3*(B3/F3) -> 80403.59 | E3: Saudi Arabia | F3: =VLOOKUP(E3, GDP!A:C, 3, FALSE) -> 35121.663 | G3: =VLOOKUP(E3,'Russia 2018 FIFA attendance'!B:D,3,FALSE) -> 36823
A4: Jordan | B4: =VLOOKUP(A4, GDP!A:C, 3, FALSE) -> 4618.0959 | C4: AFC | D4: =G4*(B4/F4) -> 4841.8022 | E4: Saudi Arabia | F4: =VLOOKUP(E4, GDP!A:C, 3, FALSE) -> 35121.663 | G4: =VLOOKUP(E4,'Russia 2018 FIFA attendance'!B:D,3,FALSE) -> 36823
A5: Iraq | B5: =VLOOKUP(A5, GDP!A:C, 3, FALSE) -> 6073.61 | C5: AFC | D5: =G5*(B5/F5) -> 49385.378 | E5: Iran | F5: =VLOOKUP(E5, GDP!A:C, 3, FALSE) -> 5190.1696 | G5: =VLOOKUP(E5,'Russia 2018 FIFA attendance'!B:D,3,FALSE) -> 42202
A6: Algeria | B6: =VLOOKUP(A6, GDP!A:C, 3, FALSE) -> 5752.9908 | C6: CAF | D6: =G6*(B6/F6) -> 56501.56 | E6: Tunisia | F6: =VLOOKUP(E6, GDP!A:C, 3, FALSE) -> 4181.1379 | G6: =VLOOKUP(E6,'Russia 2018 FIFA attendance'!B:D,3,FALSE) -> 41064
A7: Côte d’Ivoire | B7: =VLOOKUP(A7, GDP!A:C, 3, FALSE) -> 2727.8935 | C7: CAF | D7: =G7*(B7/F7) -> 64566.044 | E7: Senegal | F7: =VLOOKUP(E7, GDP!A:C, 3, FALSE) -> 1773.2183 | G7: =VLOOKUP(E7,'Russia 2018 FIFA attendance'!B:D,3,FALSE) -> 41970
A8: South Africa | B8: =VLOOKUP(A8, GDP!A:C, 3, FALSE) -> 6267.1868 | C8: CAF | D8: =G8*(B8/F8) -> 50714.208 | E8: Egypt | F8: =VLOOKUP(E8, GDP!A:C, 3, FALSE) -> 3338.4737 | G8: =VLOOKUP(E8,'Russia 2018 FIFA attendance'!B:D,3,FALSE) -> 27015
A9: Cabo Verde | B9: =VLOOKUP(A9, GDP!A:C, 3, FALSE) -> 5192.4816 | C9: CAF | D9: =G9*(B9/F9) -> 122899.96 | E9: Senegal | F9: =VLOOKUP(E9, GDP!A:C, 3, FALSE) -> 1773.2183 | G9: =VLOOKUP(E9,'Russia 2018 FIFA attendance'!B:D,3,FALSE) -> 41970
A10: Ghana | B10: =VLOOKUP(A10, GDP!A:C, 3, FALSE) -> 2390.7724 | C10: CAF | D10: =G10*(B10/F10) -> 56586.782 | E10: Senegal | F10: =VLOOKUP(E10, GDP!A:C, 3, FALSE) -> 1773.2183 | G10: =VLOOKUP(E10,'Russia 2018 FIFA attendance'!B:D,3,FALSE) -> 41970
A11: DR Congo | B11: =VLOOKUP(A11, GDP!A:C, 3, FALSE) -> 649.38334 | C11: CAF | D11: =G11*(B11/F11) -> 5254.8237 | E11: Egypt | F11: =VLOOKUP(E11, GDP!A:C, 3, FALSE) -> 3338.4737 | G11: =VLOOKUP(E11,'Russia 2018 FIFA attendance'!B:D,3,FALSE) -> 27015
A12: USA | B12: =VLOOKUP(A12, GDP!A:C, 3, FALSE) -> 84534.041 | C12: CONCACAF | D12: =G12*(B12/F12) -> 197012.76 | E12: Mexico | F12: =VLOOKUP(E12, GDP!A:C, 3, FALSE) -> 14185.781 | G12: =VLOOKUP(E12,'Russia 2018 FIFA attendance'!B:D,3,FALSE) -> 33061
A13: Canada | B13: =VLOOKUP(A13, GDP!A:C, 3, FALSE) -> 54340.348 | C13: CONCACAF | D13: =G13*(B13/F13) -> 126644.15 | E13: Mexico | F13: =VLOOKUP(E13, GDP!A:C, 3, FALSE) -> 14185.781 | G13: =VLOOKUP(E13,'Russia 2018 FIFA attendance'!B:D,3,FALSE) -> 33061
... A25: Turkiye | B25: =VLOOKUP(A25, GDP!A:C, 3, FALSE) -> 15892.716 | C25: UEFA | D25: =G25*(B25/F25) -> 33039.724 | E25: Croatia | F25: =VLOOKUP(E25, GDP!A:C, 3, FALSE) -> 24050.44 | G25: =VLOOKUP(E25,'Russia 2018 FIFA attendance'!B:D,3,FALSE) -> 49999

Sheet All attendance
A1: Countries | B1: Available average attendance (2018) | C1: Relative Demand Scaling | D1: Estimated attendance
A2: USA | B2: ='Missing country attendance'!D12 -> 197012.76 | C2: =B2/MAX($B$2:$B$49) -> 1 | D2: =C2*59726*12%*91% -> 6522.0792
A3: Canada | B3: ='Missing country attendance'!D13 -> 126644.15 | C3: =B3/MAX($B$2:$B$49) -> 0.64282208 | D3: =C3*59726*12%*91% -> 4192.5365
A4: Cabo Verde | B4: ='Missing country attendance'!D9 -> 122899.96 | C4: =B4/MAX($B$2:$B$49) -> 0.62381724 | D4: =C4*59726*12%*91% -> 4068.5854
A5: Qatar | B5: ='Missing country attendance'!D3 -> 80403.59 | C5: =B5/MAX($B$2:$B$49) -> 0.40811362 | D5: =C5*59726*12%*91% -> 2661.7493
A6: Norway | B6: ='Missing country attendance'!D21 -> 72541.454 | C6: =B6/MAX($B$2:$B$49) -> 0.36820688 | D6: =C6*59726*12%*91% -> 2401.4745
A7: Côte d’Ivoire | B7: ='Missing country attendance'!D7 -> 64566.044 | C7: =B7/MAX($B$2:$B$49) -> 0.32772519 | D7: =C7*59726*12%*91% -> 2137.4496
A8: Austria | B8: ='Missing country attendance'!D20 -> 63508.853 | C8: =B8/MAX($B$2:$B$49) -> 0.32235908 | D8: =C8*59726*12%*91% -> 2102.4515
A9: Morocco | B9: ='Russia 2018 FIFA attendance'!D2 -> 62548 | C9: =B9/MAX($B$2:$B$49) -> 0.31748197 | D9: =C9*59726*12%*91% -> 2070.6426
A10: Germany | B10: ='Russia 2018 FIFA attendance'!D3 -> 61149 | C10: =B10/MAX($B$2:$B$49) -> 0.31038091 | D10: =C10*59726*12%*91% -> 2024.3289
A11: Portugal | B11: ='Russia 2018 FIFA attendance'!D4 -> 60939 | C11: =B11/MAX($B$2:$B$49) -> 0.30931499 | D11: =C11*59726*12%*91% -> 2017.3769
A12: Denmark | B12: ='Russia 2018 FIFA attendance'!D5 -> 59369 | C12: =B12/MAX($B$2:$B$49) -> 0.30134596 | D12: =C12*59726*12%*91% -> 1965.4022
A13: Netherlands | B13: ='Missing country attendance'!D19 -> 57639.97 | C13: =B13/MAX($B$2:$B$49) -> 0.29256973 | D13: =C13*59726*12%*91% -> 1908.1629
A14: Ghana | B14: ='Missing country attendance'!D10 -> 56586.782 | C14: =B14/MAX($B$2:$B$49) -> 0.28722394 | D14: =C14*59726*12%*91% -> 1873.2973
A15: Algeria | B15: ='Missing country attendance'!D6 -> 56501.56 | C15: =B15/MAX($B$2:$B$49) -> 0.28679137 | D15: =C15*59726*12%*91% -> 1870.476
A16: Spain | B16: ='Russia 2018 FIFA attendance'!D6 -> 55992 | C16: =B16/MAX($B$2:$B$49) -> 0.28420494 | D16: =C16*59726*12%*91% -> 1853.6071
A17: France | B17: ='Russia 2018 FIFA attendance'!D7 -> 51848 | C17: =B17/MAX($B$2:$B$49) -> 0.26317077 | D17: =C17*59726*12%*91% -> 1716.4206
A18: South Africa | B18: ='Missing country attendance'!D8 -> 50714.208 | C18: =B18/MAX($B$2:$B$49) -> 0.25741586 | D18: =C18*59726*12%*91% -> 1678.8866
A19: Croatia | B19: ='Russia 2018 FIFA attendance'!D8 -> 49999 | C19: =B19/MAX($B$2:$B$49) -> 0.25378559 | D19: =C19*59726*12%*91% -> 1655.2097
A20: Iraq | B20: ='Missing country attendance'!D5 -> 49385.378 | C20: =B20/MAX($B$2:$B$49) -> 0.25067096 | D20: =C20*59726*12%*91% -> 1634.8959
A21: Belgium | B21: ='Russia 2018 FIFA attendance'!D9 -> 48330 | C21: =B21/MAX($B$2:$B$49) -> 0.24531406 | D21: =C21*59726*12%*91% -> 1599.9577
A22: Brazil | B22: ='Russia 2018 FIFA attendance'!D10 -> 48105 | C22: =B22/MAX($B$2:$B$49) -> 0.244172 | D22: =C22*59726*12%*91% -> 1592.5091
A23: Curaçao | B23: ='Missing country attendance'!D14 -> 44290.14 | C23: =B23/MAX($B$2:$B$49) -> 0.22480848 | D23: =C23*59726*12%*91% -> 1466.2187
A24: Australia | B24: ='Russia 2018 FIFA attendance'!D11 -> 44073 | C24: =B24/MAX($B$2:$B$49) -> 0.22370632 | D24: =C24*59726*12%*91% -> 1459.0303
A25: Argentina | B25: ='Russia 2018 FIFA attendance'!D12 -> 43754 | C25: =B25/MAX($B$2:$B$49) -> 0.22208714 | D25: =C25*59726*12%*91% -> 1448.4699
A26: Switzerland | B26: ='Russia 2018 FIFA attendance'!D13 -> 43319 | C26: =B26/MAX($B$2:$B$49) -> 0.21987916 | D26: =C26*59726*12%*91% -> 1434.0693
A27: Uruguay | B27: ='Russia 2018 FIFA attendance'!D14 -> 43064 | C27: =B27/MAX($B$2:$B$49) -> 0.21858483 | D27: =C27*59726*12%*91% -> 1425.6275
A28: Korea Republic | B28: ='Russia 2018 FIFA attendance'!D15 -> 42654 | C28: =B28/MAX($B$2:$B$49) -> 0.21650374 | D28: =C28*59726*12%*91% -> 1412.0546
A29: Colombia | B29: ='Russia 2018 FIFA attendance'!D16 -> 42516 | C29: =B29/MAX($B$2:$B$49) -> 0.21580328 | D29: =C29*59726*12%*91% -> 1407.4861
A30: Iran | B30: ='Russia 2018 FIFA attendance'!D17 -> 42202 | C30: =B30/MAX($B$2:$B$49) -> 0.21420947 | D30: =C30*59726*12%*91% -> 1397.0912
A31: Senegal | B31: ='Russia 2018 FIFA attendance'!D18 -> 41970 | C31: =B31/MAX($B$2:$B$49) -> 0.21303189 | D31: =C31*59726*12%*91% -> 1389.4108
A32: Tunisia | B32: ='Russia 2018 FIFA attendance'!D19 -> 41064 | C32: =B32/MAX($B$2:$B$49) -> 0.2084332 | D32: =C32*59726*12%*91% -> 1359.4178
A33: England | B33: ='Russia 2018 FIFA attendance'!D20 -> 38646 | C33: =B33/MAX($B$2:$B$49) -> 0.19615988 | D33: =C33*59726*12%*91% -> 1279.3703
A34: Scotland | B34: ='Missing country attendance'!D22 -> 38646 | C34: =B34/MAX($B$2:$B$49) -> 0.19615988 | D34: =C34*59726*12%*91% -> 1279.3703
A35: Japan | B35: ='Russia 2018 FIFA attendance'!D21 -> 37381 | C35: =B35/MAX($B$2:$B$49) -> 0.18973898 | D35: =C35*59726*12%*91% -> 1237.4926
A36: Panama | B36: ='Russia 2018 FIFA attendance'!D22 -> 37168 | C36: =B36/MAX($B$2:$B$49) -> 0.18865783 | D36: =C36*59726*12%*91% -> 1230.4413
A37: Ecuador | B37: ='Missing country attendance'!D16 -> 36908.357 | C37: =B37/MAX($B$2:$B$49) -> 0.18733993 | D37: =C37*59726*12%*91% -> 1221.8459
A38: Saudi Arabia | B38: ='Russia 2018 FIFA attendance'!D23 -> 36823 | C38: =B38/MAX($B$2:$B$49) -> 0.18690667 | D38: =C38*59726*12%*91% -> 1219.0201
A39: New Zealand | B39: ='Missing country attendance'!D18 -> 33567.896 | C39: =B39/MAX($B$2:$B$49) -> 0.17038437 | D39: =C39*59726*12%*91% -> 1111.2604
A40: Mexico | B40: ='Russia 2018 FIFA attendance'!D24 -> 33061 | C40: =B40/MAX($B$2:$B$49) -> 0.16781146 | D40: =C40*59726*12%*91% -> 1094.4797
...

Sheet Spectator index
A1: Country | B1: Expected attendance | C1: MetLife Stadium | D1: Estadio Azteca | E1: AT&T Stadium | F1: SoFi Stadium | G1: Levi's Stadium | H1: NRG Stadium | I1: GEHA Field at Arrowhead Stadium | J1: Mercedes-Benz Stadium | K1: Lincoln Financial Field | L1: Lumen Field | M1: Hard Rock Stadium | N1: Gillette Stadium | O1: Estadio BBVA | P1: BC Place | Q1: Estadio Akron | R1: BMO Field | S1: Probability | T1: weighted avg | U1: SI | V1: SI percentage (%) | W1: Country
A2: Mexico | B2: =VLOOKUP(A2, 'All attendance'!A:D, 4, FALSE) -> 1094.4797 | C2: =B2/Stadium!$G$2 -> 0.12755431 | D2: =B2/Stadium!$G$3 -> 0.13773888 | E2: =B2/Stadium!$G$4 -> 0.14293243 | F2: =B2/Stadium!$G$5 -> 0.14390104 | G2: =B2/Stadium!$G$6 -> 0.14443815 | H2: =B2/Stadium!$G$7 -> 0.14672172 | I2: =B2/Stadium!$G$8 -> 0.14845596 | J2: =B2/Stadium!$G$9 -> 0.14874458 | K2: =B2/Stadium!$G$10 -> 0.15225831 | L2: =B2/Stadium!$G$11 -> 0.15390427 | M2: =B2/Stadium!$G$12 -> 0.15638245 | N2: =B2/Stadium!$G$13 -> 0.1570588 | O2: =B2/Stadium!$G$14 -> 0.20000215 | P2: =B2/Stadium!$G$15 -> 0.20529501 | Q2: =B2/Stadium!$G$16 -> 0.22609311 | R2: =B2/Stadium!$G$17 -> 0.22616964 | S2: =4.5/72 -> 0.0625 | T2: =S2*SUM(C2:R2) -> 0.16360318 | U2: =IF(OR(A2="USA", A2="Mexico", A2="Canada"), 1, MIN(1, T2)) -> 1 | V2: =U2*100 -> 100 | W2: Mexico
A3: USA | B3: =VLOOKUP(A3, 'All attendance'!A:D, 4, FALSE) -> 6522.0792 | C3: =B3/Stadium!$G$2 -> 0.76010487 | D3: =B3/Stadium!$G$3 -> 0.82079543 | E3: =B3/Stadium!$G$4 -> 0.8517441 | F3: =B3/Stadium!$G$5 -> 0.85751615 | G3: =B3/Stadium!$G$6 -> 0.86071681 | H3: =B3/Stadium!$G$7 -> 0.87432478 | I3: =B3/Stadium!$G$8 -> 0.88465925 | J3: =B3/Stadium!$G$9 -> 0.88637915 | K3: =B3/Stadium!$G$10 -> 0.90731767 | L3: =B3/Stadium!$G$11 -> 0.91712605 | M3: =B3/Stadium!$G$12 -> 0.93189371 | N3: =B3/Stadium!$G$13 -> 0.93592416 | O3: =B3/Stadium!$G$14 -> 1.1918265 | P3: =B3/Stadium!$G$15 -> 1.223367 | Q3: =B3/Stadium!$G$16 -> 1.3473043 | R3: =B3/Stadium!$G$17 -> 1.3477604 | S3: =4.5/72 -> 0.0625 | T3: =S3*SUM(C3:R3) -> 0.97492252 | U3: =IF(OR(A3="USA", A3="Mexico", A3="Canada"), 1, MIN(1, T3)) -> 1 | V3: =U3*100 -> 100 | W3: USA
A4: Canada | B4: =VLOOKUP(A4, 'All attendance'!A:D, 4, FALSE) -> 4192.5365 | C4: =B4/Stadium!$G$2 -> 0.48861219 | D4: =B4/Stadium!$G$3 -> 0.52762542 | E4: =B4/Stadium!$G$4 -> 0.54751991 | F4: =B4/Stadium!$G$5 -> 0.55123031 | G4: =B4/Stadium!$G$6 -> 0.55328777 | H4: =B4/Stadium!$G$7 -> 0.56203527 | I4: =B4/Stadium!$G$8 -> 0.5686785 | J4: =B4/Stadium!$G$9 -> 0.56978409 | K4: =B4/Stadium!$G$10 -> 0.58324383 | L4: =B4/Stadium!$G$11 -> 0.58954888 | M4: =B4/Stadium!$G$12 -> 0.59904185 | N4: =B4/Stadium!$G$13 -> 0.60163271 | O4: =B4/Stadium!$G$14 -> 0.76613237 | P4: =B4/Stadium!$G$15 -> 0.78640731 | Q4: =B4/Stadium!$G$16 -> 0.86607695 | R4: =B4/Stadium!$G$17 -> 0.86637011 | S4: =4.5/72 -> 0.0625 | T4: =S4*SUM(C4:R4) -> 0.62670172 | U4: =IF(OR(A4="USA", A4="Mexico", A4="Canada"), 1, MIN(1, T4)) -> 1 | V4: =U4*100 -> 100 | W4: Canada
A5: Cabo Verde | B5: =VLOOKUP(A5, 'All attendance'!A:D, 4, FALSE) -> 4068.5854 | C5: =B5/Stadium!$G$2 -> 0.47416652 | D5: =B5/Stadium!$G$3 -> 0.51202634 | E5: =B5/Stadium!$G$4 -> 0.53133265 | F5: =B5/Stadium!$G$5 -> 0.53493336 | G5: =B5/Stadium!$G$6 -> 0.53692998 | H5: =B5/Stadium!$G$7 -> 0.54541887 | I5: =B5/Stadium!$G$8 -> 0.55186569 | J5: =B5/Stadium!$G$9 -> 0.55293859 | K5: =B5/Stadium!$G$10 -> 0.5660004 | L5: =B5/Stadium!$G$11 -> 0.57211904 | M5: =B5/Stadium!$G$12 -> 0.58133136 | N5: =B5/Stadium!$G$13 -> 0.58384562 | O5: =B5/Stadium!$G$14 -> 0.7434819 | P5: =B5/Stadium!$G$15 -> 0.76315742 | Q5: =B5/Stadium!$G$16 -> 0.84047165 | R5: =B5/Stadium!$G$17 -> 0.84075614 | S5: =4.5/72 -> 0.0625 | T5: =S5*SUM(C5:R5) -> 0.60817347 | U5: =IF(OR(A5="USA", A5="Mexico", A5="Canada"), 1, MIN(1, T5)) -> 0.60817347 | V5: =U5*100 -> 60.817347 | W5: Cabo Verde
A6: Qatar | B6: =VLOOKUP(A6, 'All attendance'!A:D, 4, FALSE) -> 2661.7493 | C6: =B6/Stadium!$G$2 -> 0.31020915 | D6: =B6/Stadium!$G$3 -> 0.33497779 | E6: =B6/Stadium!$G$4 -> 0.34760837 | F6: =B6/Stadium!$G$5 -> 0.34996402 | G6: =B6/Stadium!$G$6 -> 0.35127025 | H6: =B6/Stadium!$G$7 -> 0.35682385 | I6: =B6/Stadium!$G$8 -> 0.36104149 | J6: =B6/Stadium!$G$9 -> 0.3617434 | K6: =B6/Stadium!$G$10 -> 0.37028869 | L6: =B6/Stadium!$G$11 -> 0.37429163 | M6: =B6/Stadium!$G$12 -> 0.38031851 | N6: =B6/Stadium!$G$13 -> 0.38196339 | O6: =B6/Stadium!$G$14 -> 0.48640061 | P6: =B6/Stadium!$G$15 -> 0.49927273 | Q6: =B6/Stadium!$G$16 -> 0.54985323 | R6: =B6/Stadium!$G$17 -> 0.55003935 | S6: =4.5/72 -> 0.0625 | T6: =S6*SUM(C6:R6) -> 0.39787915 | U6: =IF(OR(A6="USA", A6="Mexico", A6="Canada"), 1, MIN(1, T6)) -> 0.39787915 | V6: =U6*100 -> 39.787915 | W6: Qatar
A7: Norway | B7: =VLOOKUP(A7, 'All attendance'!A:D, 4, FALSE) -> 2401.4745 | C7: =B7/Stadium!$G$2 -> 0.27987584 | D7: =B7/Stadium!$G$3 -> 0.30222253 | E7: =B7/Stadium!$G$4 -> 0.31361804 | F7: =B7/Stadium!$G$5 -> 0.31574335 | G7: =B7/Stadium!$G$6 -> 0.31692185 | H7: =B7/Stadium!$G$7 -> 0.3219324 | I7: =B7/Stadium!$G$8 -> 0.32573762 | J7: =B7/Stadium!$G$9 -> 0.3263709 | K7: =B7/Stadium!$G$10 -> 0.33408061 | L7: =B7/Stadium!$G$11 -> 0.33769213 | M7: =B7/Stadium!$G$12 -> 0.34312968 | N7: =B7/Stadium!$G$13 -> 0.34461372 | O7: =B7/Stadium!$G$14 -> 0.43883871 | P7: =B7/Stadium!$G$15 -> 0.45045215 | Q7: =B7/Stadium!$G$16 -> 0.49608672 | R7: =B7/Stadium!$G$17 -> 0.49625464 | S7: =4.5/72 -> 0.0625 | T7: =S7*SUM(C7:R7) -> 0.35897318 | U7: =IF(OR(A7="USA", A7="Mexico", A7="Canada"), 1, MIN(1, T7)) -> 0.35897318 | V7: =U7*100 -> 35.897318 | W7: Norway
A8: Côte d’Ivoire | B8: =VLOOKUP(A8, 'All attendance'!A:D, 4, FALSE) -> 2137.4496 | C8: =B8/Stadium!$G$2 -> 0.24910551 | D8: =B8/Stadium!$G$3 -> 0.26899534 | E8: =B8/Stadium!$G$4 -> 0.279138 | F8: =B8/Stadium!$G$5 -> 0.28102964 | G8: =B8/Stadium!$G$6 -> 0.28207858 | H8: =B8/Stadium!$G$7 -> 0.28653825 | I8: =B8/Stadium!$G$8 -> 0.28992512 | J8: =B8/Stadium!$G$9 -> 0.29048877 | K8: =B8/Stadium!$G$10 -> 0.29735085 | L8: =B8/Stadium!$G$11 -> 0.30056531 | M8: =B8/Stadium!$G$12 -> 0.30540504 | N8: =B8/Stadium!$G$13 -> 0.30672592 | O8: =B8/Stadium!$G$14 -> 0.39059156 | P8: =B8/Stadium!$G$15 -> 0.40092818 | Q8: =B8/Stadium!$G$16 -> 0.44154556 | R8: =B8/Stadium!$G$17 -> 0.44169502 | S8: =4.5/72 -> 0.0625 | T8: =S8*SUM(C8:R8) -> 0.31950667 | U8: =IF(OR(A8="USA", A8="Mexico", A8="Canada"), 1, MIN(1, T8)) -> 0.31950667 | V8: =U8*100 -> 31.950667 | W8: Côte d’Ivoire
A9: Austria | B9: =VLOOKUP(A9, 'All attendance'!A:D, 4, FALSE) -> 2102.4515 | C9: =B9/Stadium!$G$2 -> 0.24502671 | D9: =B9/Stadium!$G$3 -> 0.26459086 | E9: =B9/Stadium!$G$4 -> 0.27456745 | F9: =B9/Stadium!$G$5 -> 0.27642812 | G9: =B9/Stadium!$G$6 -> 0.27745988 | H9: =B9/Stadium!$G$7 -> 0.28184653 | I9: =B9/Stadium!$G$8 -> 0.28517794 | J9: =B9/Stadium!$G$9 -> 0.28573237 | K9: =B9/Stadium!$G$10 -> 0.29248209 | L9: =B9/Stadium!$G$11 -> 0.29564391 | M9: =B9/Stadium!$G$12 -> 0.3004044 | N9: =B9/Stadium!$G$13 -> 0.30170365 | O9: =B9/Stadium!$G$14 -> 0.38419609 | P9: =B9/Stadium!$G$15 -> 0.39436346 | Q9: =B9/Stadium!$G$16 -> 0.43431578 | R9: =B9/Stadium!$G$17 -> 0.43446279 | S9: =4.5/72 -> 0.0625 | T9: =S9*SUM(C9:R9) -> 0.31427513 | U9: =IF(OR(A9="USA", A9="Mexico", A9="Canada"), 1, MIN(1, T9)) -> 0.31427513 | V9: =U9*100 -> 31.427513 | W9: Austria
A10: Morocco | B10: =VLOOKUP(A10, 'All attendance'!A:D, 4, FALSE) -> 2070.6426 | C10: =B10/Stadium!$G$2 -> 0.24131959 | D10: =B10/Stadium!$G$3 -> 0.26058775 | E10: =B10/Stadium!$G$4 -> 0.2704134 | F10: =B10/Stadium!$G$5 -> 0.27224592 | G10: =B10/Stadium!$G$6 -> 0.27326207 | H10: =B10/Stadium!$G$7 -> 0.27758236 | I10: =B10/Stadium!$G$8 -> 0.28086336 | J10: =B10/Stadium!$G$9 -> 0.2814094 | K10: =B10/Stadium!$G$10 -> 0.288057 | L10: =B10/Stadium!$G$11 -> 0.29117099 | M10: =B10/Stadium!$G$12 -> 0.29585945 | N10: =B10/Stadium!$G$13 -> 0.29713905 | O10: =B10/Stadium!$G$14 -> 0.37838342 | P10: =B10/Stadium!$G$15 -> 0.38839697 | Q10: =B10/Stadium!$G$16 -> 0.42774483 | R10: =B10/Stadium!$G$17 -> 0.42788962 | S10: =4.5/72 -> 0.0625 | T10: =S10*SUM(C10:R10) -> 0.30952032 | U10: =IF(OR(A10="USA", A10="Mexico", A10="Canada"), 1, MIN(1, T10)) -> 0.30952032 | V10: =U10*100 -> 30.952032 | W10: Morocco
A11: Germany | B11: =VLOOKUP(A11, 'All attendance'!A:D, 4, FALSE) -> 2024.3289 | C11: =B11/Stadium!$G$2 -> 0.23592204 | D11: =B11/Stadium!$G$3 -> 0.25475923 | E11: =B11/Stadium!$G$4 -> 0.26436511 | F11: =B11/Stadium!$G$5 -> 0.26615664 | G11: =B11/Stadium!$G$6 -> 0.26715007 | H11: =B11/Stadium!$G$7 -> 0.27137372 | I11: =B11/Stadium!$G$8 -> 0.27458134 | J11: =B11/Stadium!$G$9 -> 0.27511517 | K11: =B11/Stadium!$G$10 -> 0.28161408 | L11: =B11/Stadium!$G$11 -> 0.28465842 | M11: =B11/Stadium!$G$12 -> 0.28924202 | N11: =B11/Stadium!$G$13 -> 0.29049299 | O11: =B11/Stadium!$G$14 -> 0.36992019 | P11: =B11/Stadium!$G$15 -> 0.37970976 | Q11: =B11/Stadium!$G$16 -> 0.41817754 | R11: =B11/Stadium!$G$17 -> 0.41831908 | S11: =4.5/72 -> 0.0625 | T11: =S11*SUM(C11:R11) -> 0.30259734 | U11: =IF(OR(A11="USA", A11="Mexico", A11="Canada"), 1, MIN(1, T11)) -> 0.30259734 | V11: =U11*100 -> 30.259734 | W11: Germany
A12: Portugal | B12: =VLOOKUP(A12, 'All attendance'!A:D, 4, FALSE) -> 2017.3769 | C12: =B12/Stadium!$G$2 -> 0.23511183 | D12: =B12/Stadium!$G$3 -> 0.25388433 | E12: =B12/Stadium!$G$4 -> 0.26345722 | F12: =B12/Stadium!$G$5 -> 0.2652426 | G12: =B12/Stadium!$G$6 -> 0.26623261 | H12: =B12/Stadium!$G$7 -> 0.27044176 | I12: =B12/Stadium!$G$8 -> 0.27363837 | J12: =B12/Stadium!$G$9 -> 0.27417036 | K12: =B12/Stadium!$G$10 -> 0.28064695 | L12: =B12/Stadium!$G$11 -> 0.28368084 | M12: =B12/Stadium!$G$12 -> 0.28824869 | N12: =B12/Stadium!$G$13 -> 0.28949537 | O12: =B12/Stadium!$G$14 -> 0.36864979 | P12: =B12/Stadium!$G$15 -> 0.37840575 | Q12: =B12/Stadium!$G$16 -> 0.41674142 | R12: =B12/Stadium!$G$17 -> 0.41688248 | S12: =4.5/72 -> 0.0625 | T12: =S12*SUM(C12:R12) -> 0.30155815 | U12: =IF(OR(A12="USA", A12="Mexico", A12="Canada"), 1, MIN(1, T12)) -> 0.30155815 | V12: =U12*100 -> 30.155815 | W12: Portugal
A13: Denmark | B13: =VLOOKUP(A13, 'All attendance'!A:D, 4, FALSE) -> 1965.4022 | C13: =B13/Stadium!$G$2 -> 0.22905453 | D13: =B13/Stadium!$G$3 -> 0.24734339 | E13: =B13/Stadium!$G$4 -> 0.25666965 | F13: =B13/Stadium!$G$5 -> 0.25840903 | G13: =B13/Stadium!$G$6 -> 0.25937353 | H13: =B13/Stadium!$G$7 -> 0.26347424 | I13: =B13/Stadium!$G$8 -> 0.26658849 | J13: =B13/Stadium!$G$9 -> 0.26710678 | K13: =B13/Stadium!$G$10 -> 0.27341652 | L13: =B13/Stadium!$G$11 -> 0.27637223 | M13: =B13/Stadium!$G$12 -> 0.28082241 | N13: =B13/Stadium!$G$13 -> 0.28203697 | O13: =B13/Stadium!$G$14 -> 0.3591521 | P13: =B13/Stadium!$G$15 -> 0.3686567 | Q13: =B13/Stadium!$G$16 -> 0.40600471 | R13: =B13/Stadium!$G$17 -> 0.40614214 | S13: =4.5/72 -> 0.0625 | T13: =S13*SUM(C13:R13) -> 0.29378896 | U13: =IF(OR(A13="USA", A13="Mexico", A13="Canada"), 1, MIN(1, T13)) -> 0.29378896 | V13: =U13*100 -> 29.378896 | W13: Denmark
... A49: Haiti | B49: =VLOOKUP(A49, 'All attendance'!A:D, 4, FALSE) -> 137.58896 | C49: =B49/Stadium!$G$2 -> 0.016035077 | D49: =B49/Stadium!$G$3 -> 0.017315397 | E49: =B49/Stadium!$G$4 -> 0.017968287 | F49: =B49/Stadium!$G$5 -> 0.018090053 | G49: =B49/Stadium!$G$6 -> 0.018157574 | H49: =B49/Stadium!$G$7 -> 0.018444646 | I49: =B49/Stadium!$G$8 -> 0.01866266 | J49: =B49/Stadium!$G$9 -> 0.018698943 | K49: =B49/Stadium!$G$10 -> 0.019140659 | L49: =B49/Stadium!$G$11 -> 0.019347576 | M49: =B49/Stadium!$G$12 -> 0.019659113 | N49: =B49/Stadium!$G$13 -> 0.019744138 | O49: =B49/Stadium!$G$14 -> 0.025142621 | P49: =B49/Stadium!$G$15 -> 0.025807996 | Q49: =B49/Stadium!$G$16 -> 0.028422562 | R49: =B49/Stadium!$G$17 -> 0.028432183 | S49: =4.5/72 -> 0.0625 | T49: =S49*SUM(C49:R49) -> 0.020566843 | U49: =IF(OR(A49="USA", A49="Mexico", A49="Canada"), 1, MIN(1, T49)) -> 0.020566843 | V49: =U49*100 -> 2.0566843 | W49: Haiti

Sheet groups_long
A1: group_num | B1: team | C1: rank_in_group | D1: spectator_index
A2: 1 | B2: Spain | C2: 1 | D2: =_xlfn.XLOOKUP(B2,'Spectator index'!$A:$A,'Spectator index'!$U:$U,"") -> 0.2770778
A3: 1 | B3: Korea Republic | C3: 2 | D3: =_xlfn.XLOOKUP(B3,'Spectator index'!$A:$A,'Spectator index'!$U:$U,"") -> 0.21107437
A4: 1 | B4: Paraguay | C4: 3 | D4: =_xlfn.XLOOKUP(B4,'Spectator index'!$A:$A,'Spectator index'!$U:$U,"") -> 0.14813412
A5: 1 | B5: Cabo Verde | C5: 4 | D5: =_xlfn.XLOOKUP(B5,'Spectator index'!$A:$A,'Spectator index'!$U:$U,"") -> 0.60817347
A6: 2 | B6: Argentina | C6: 1 | D6: =_xlfn.XLOOKUP(B6,'Spectator index'!$A:$A,'Spectator index'!$U:$U,"") -> 0.21651775
A7: 2 | B7: USA | C7: 2 | D7: =_xlfn.XLOOKUP(B7,'Spectator index'!$A:$A,'Spectator index'!$U:$U,"") -> 1
A8: 2 | B8: Norway | C8: 3 | D8: =_xlfn.XLOOKUP(B8,'Spectator index'!$A:$A,'Spectator index'!$U:$U,"") -> 0.35897318
A9: 2 | B9: New Zealand | C9: 4 | D9: =_xlfn.XLOOKUP(B9,'Spectator index'!$A:$A,'Spectator index'!$U:$U,"") -> 0.16611156
A10: 3 | B10: Brazil | C10: 1 | D10: =_xlfn.XLOOKUP(B10,'Spectator index'!$A:$A,'Spectator index'!$U:$U,"") -> 0.23804878
A11: 3 | B11: Denmark | C11: 2 | D11: =_xlfn.XLOOKUP(B11,'Spectator index'!$A:$A,'Spectator index'!$U:$U,"") -> 0.29378896
A12: 3 | B12: Panama | C12: 3 | D12: =_xlfn.XLOOKUP(B12,'Spectator index'!$A:$A,'Spectator index'!$U:$U,"") -> 0.18392677
A13: 3 | B13: Qatar | C13: 4 | D13: =_xlfn.XLOOKUP(B13,'Spectator index'!$A:$A,'Spectator index'!$U:$U,"") -> 0.39787915
... A49: 12 | B49: DR Congo | C49: 4 | D49: =_xlfn.XLOOKUP(B49,'Spectator index'!$A:$A,'Spectator index'!$U:$U,"") -> 0.026003625

Sheet match_list_long
A1: row_set_id | B1: slot_id | C1: match_code | D1: group_letter | E1: rank_a | F1: rank_b
A2: 1 | B2: 3 | C2: D3-D4 | D2: D | E2: 3 | F2: 4
A3: 1 | B3: 8 | C3: B1-B3 | D3: B | E3: 1 | F3: 3
A4: 1 | B4: 11 | C4: G2-G4 | D4: G | E4: 2 | F4: 4
A5: 1 | B5: 14 | C5: B1-B4 | D5: B | E5: 1 | F5: 4
A6: 1 | B6: 16 | C6: G1-G4 | D6: G | E6: 1 | F6: 4
A7: 2 | B7: 5 | C7: G1-G2 | D7: G | E7: 1 | F7: 2
A8: 2 | B8: 9 | C8: D1-D3 | D8: D | E8: 1 | F8: 3
A9: 2 | B9: 14 | C9: B2-B3 | D9: B | E9: 2 | F9: 3
A10: 2 | B10: 16 | C10: G2-G3 | D10: G | E10: 2 | F10: 3
A11: 3 | B11: 3 | C11: B3-B4 | D11: B | E11: 3 | F11: 4
A12: 3 | B12: 6 | C12: J3-J4 | D12: J | E12: 3 | F12: 4
A13: 3 | B13: 9 | C13: D2-D4 | D13: D | E13: 2 | F13: 4
... A73: 16 | B73: 17 | C73: L1-L4 | D73: L | E73: 1 | F73: 4

Sheet match_grid_norm
A1: row_set_id | B1: slot_1 | C1: slot_2 | D1: slot_3 | E1: slot_4 | F1: slot_5 | G1: slot_6 | H1: slot_7 | I1: slot_8 | J1: slot_9 | K1: slot_10 | L1: slot_11 | M1: slot_12 | N1: slot_13 | O1: slot_14 | P1: slot_15 | Q1: slot_16 | R1: slot_17
A2: 1 | D2: D3-D4 | I2: B1-B3 | L2: G2-G4 | O2: B1-B4 | Q2: G1-G4
A3: 2 | F3: G1-G2 | J3: D1-D3 | O3: B2-B3 | Q3: G2-G3
A4: 3 | D4: B3-B4 | G4: J3-J4 | J4: D2-D4 | M4: J2-J4 | P4: D2-D3
A5: 4 | C5: D1-D2 | F5: G3-G4 | I5: B2-B4 | L5: G1-G3 | P5: D1-D4
A6: 5 | B6: A3-A4 | I6: A1-A3 | N6: K2-K4 | Q6: H1-H4
A7: 6 | B7: A1-A2 | H7: K3-K4 | O7: A1-A4
A8: 7 | E8: F3-F4 | K8: F2-F4 | O8: A2-A3
A9: 8 | E9: E1-E2 | H9: K1-K2 | K9: F1-F3 | N9: K1-K3 | Q9: H2-H3
A10: 9 | E10: F1-F2 | H10: L1-L2 | M10: J1-J3 | P10: F2-F3 | R10: J1-J4
A11: 10 | G11: J1-J2 | K11: E2-E4 | P11: F1-F4 | R11: J2-J3
A12: 11 | F12: H1-H2 | I12: A2-A4 | L12: H1-H3 | O12: C2-C3 | R12: K2-K3
A13: 12 | F13: H3-H4 | L13: H2-H4 | O13: C1-C4 | R13: K1-K4
A14: 13 | C14: B1-B2 | H14: L3-L4 | K14: E1-E3 | N14: L2-L4 | Q14: I2-I3
A15: 14 | D15: C3-C4 | G15: I3-I4 | J15: C2-C4 | N15: L1-L3 | Q15: I1-I4
A16: 15 | E16: E3-E4 | J16: C1-C3 | M16: I1-I3 | P16: E2-E3 | R16: L2-L3
A17: 16 | D17: C1-C2 | G17: I1-I2 | M17: I2-I4 | P17: E1-E4 | R17: L1-L4
